<?xml version="1.0" encoding="utf-8"?>
<!-- This URDF was automatically created by SolidWorks to URDF Exporter! Originally created by Stephen Brawner (brawner@gmail.com) 
     Commit Version: 1.6.0-1-g15f4949  Build Version: 1.6.7594.29634
     For more information, please see http://wiki.ros.org/sw_urdf_exporter -->
<robot
  name="urdf_Myool">
  <link
    name="base_link">
    <inertial>
      <origin
        xyz="-0.0025949 1.6653E-16 0.003175"
        rpy="0 0 0" />
      <mass
        value="2.8701" />
      <inertia
        ixx="0.019918"
        ixy="2.8362E-18"
        ixz="-8.9312E-19"
        iyy="0.042638"
        iyz="2.3214E-19"
        izz="0.061874" />
    </inertial>
    <visual>
      <origin
        xyz="0 0 0"
        rpy="0 0 0" />
      <geometry>
        <mesh
          filename="package://urdf_Myool/meshes/base_link.STL" />
      </geometry>
      <material
        name="">
        <color
          rgba="0.75294 0.75294 0.75294 1" />
      </material>
    </visual>
    <collision>
      <origin
        xyz="0 0 0"
        rpy="0 0 0" />
      <geometry>
        <mesh
          filename="package://urdf_Myool/meshes/base_link.STL" />
      </geometry>
    </collision>
  </link>
  <link
    name="Front_Right">
    <inertial>
      <origin
        xyz="-5.5511E-17 -0.021778 -6.245E-17"
        rpy="0 0 0" />
      <mass
        value="0.84556" />
      <inertia
        ixx="0.001557"
        ixy="1.5045E-19"
        ixz="3.8952E-11"
        iyy="0.0028888"
        iyz="2.8717E-09"
        izz="0.001557" />
    </inertial>
    <visual>
      <origin
        xyz="0 0 0"
        rpy="0 0 0" />
      <geometry>
        <mesh
          filename="package://urdf_Myool/meshes/Front_Right.STL" />
      </geometry>
      <material
        name="">
        <color
          rgba="0.79216 0.81961 0.93333 1" />
      </material>
    </visual>
    <collision>
      <origin
        xyz="0 0 0"
        rpy="0 0 0" />
      <geometry>
        <mesh
          filename="package://urdf_Myool/meshes/Front_Right.STL" />
      </geometry>
    </collision>
  </link>
  <joint
    name="Front_Right_Wheel"
    type="continuous">
    <origin
      xyz="0.14829 -0.21561 0.003175"
      rpy="0 0 0" />
    <parent
      link="base_link" />
    <child
      link="Front_Right" />
    <axis
      xyz="0 1 0" />
  </joint>
  <link
    name="Front_Left">
    <inertial>
      <origin
        xyz="-1.1102E-16 0.021778 9.7145E-17"
        rpy="0 0 0" />
      <mass
        value="0.84556" />
      <inertia
        ixx="0.001557"
        ixy="1.0002E-18"
        ixz="-3.8952E-11"
        iyy="0.0028888"
        iyz="-2.8717E-09"
        izz="0.001557" />
    </inertial>
    <visual>
      <origin
        xyz="0 0 0"
        rpy="0 0 0" />
      <geometry>
        <mesh
          filename="package://urdf_Myool/meshes/Front_Left.STL" />
      </geometry>
      <material
        name="">
        <color
          rgba="0.79216 0.81961 0.93333 1" />
      </material>
    </visual>
    <collision>
      <origin
        xyz="0 0 0"
        rpy="0 0 0" />
      <geometry>
        <mesh
          filename="package://urdf_Myool/meshes/Front_Left.STL" />
      </geometry>
    </collision>
  </link>
  <joint
    name="Front_Left_Wheel"
    type="continuous">
    <origin
      xyz="0.14829 0.21561 0.003175"
      rpy="0 0 0" />
    <parent
      link="base_link" />
    <child
      link="Front_Left" />
    <axis
      xyz="0 -1 0" />
  </joint>
  <link
    name="Back_Right">
    <inertial>
      <origin
        xyz="2.0751E-17 -0.0031974 -1.9429E-16"
        rpy="0 0 0" />
      <mass
        value="0.32911" />
      <inertia
        ixx="0.00015526"
        ixy="1.4693E-20"
        ixz="-1.0156E-19"
        iyy="0.0020318"
        iyz="3.1039E-21"
        izz="0.0018788" />
    </inertial>
    <visual>
      <origin
        xyz="0 0 0"
        rpy="0 0 0" />
      <geometry>
        <mesh
          filename="package://urdf_Myool/meshes/Back_Right.STL" />
      </geometry>
      <material
        name="">
        <color
          rgba="0.89804 0.91765 0.92941 1" />
      </material>
    </visual>
    <collision>
      <origin
        xyz="0 0 0"
        rpy="0 0 0" />
      <geometry>
        <mesh
          filename="package://urdf_Myool/meshes/Back_Right.STL" />
      </geometry>
    </collision>
  </link>
  <joint
    name="Back_Right_Rocker"
    type="continuous">
    <origin
      xyz="-0.15651 -0.20097 0.003175"
      rpy="0 0 0" />
    <parent
      link="base_link" />
    <child
      link="Back_Right" />
    <axis
      xyz="0 1 0" />
  </joint>
  <link
    name="Back_Right_Rear">
    <inertial>
      <origin
        xyz="-1.3878E-17 -0.021778 -6.9389E-18"
        rpy="0 0 0" />
      <mass
        value="0.84556" />
      <inertia
        ixx="0.001557"
        ixy="1.1E-09"
        ixz="2.7521E-11"
        iyy="0.0028888"
        iyz="2.6527E-09"
        izz="0.001557" />
    </inertial>
    <visual>
      <origin
        xyz="0 0 0"
        rpy="0 0 0" />
      <geometry>
        <mesh
          filename="package://urdf_Myool/meshes/Back_Right_Rear.STL" />
      </geometry>
      <material
        name="">
        <color
          rgba="0.79216 0.81961 0.93333 1" />
      </material>
    </visual>
    <collision>
      <origin
        xyz="0 0 0"
        rpy="0 0 0" />
      <geometry>
        <mesh
          filename="package://urdf_Myool/meshes/Back_Right_Rear.STL" />
      </geometry>
    </collision>
  </link>
  <joint
    name="Back_Right_Rear_Wheel"
    type="continuous">
    <origin
      xyz="-0.1016 -0.01465 0"
      rpy="0 0 0" />
    <parent
      link="Back_Right" />
    <child
      link="Back_Right_Rear" />
    <axis
      xyz="0 1 0" />
  </joint>
  <link
    name="Back_Right_Center">
    <inertial>
      <origin
        xyz="-1.3878E-17 -0.021778 -2.0817E-17"
        rpy="0 0 0" />
      <mass
        value="0.84556" />
      <inertia
        ixx="0.001557"
        ixy="1.1E-09"
        ixz="2.7521E-11"
        iyy="0.0028888"
        iyz="2.6527E-09"
        izz="0.001557" />
    </inertial>
    <visual>
      <origin
        xyz="0 0 0"
        rpy="0 0 0" />
      <geometry>
        <mesh
          filename="package://urdf_Myool/meshes/Back_Right_Center.STL" />
      </geometry>
      <material
        name="">
        <color
          rgba="0.79216 0.81961 0.93333 1" />
      </material>
    </visual>
    <collision>
      <origin
        xyz="0 0 0"
        rpy="0 0 0" />
      <geometry>
        <mesh
          filename="package://urdf_Myool/meshes/Back_Right_Center.STL" />
      </geometry>
    </collision>
  </link>
  <joint
    name="Back_Right_Center_Wjeel"
    type="continuous">
    <origin
      xyz="0.1016 -0.01465 0"
      rpy="0 0 0" />
    <parent
      link="Back_Right" />
    <child
      link="Back_Right_Center" />
    <axis
      xyz="0 1 0" />
  </joint>
  <link
    name="Back_Left">
    <inertial>
      <origin
        xyz="4.3031E-17 0.0031526 -1.9429E-16"
        rpy="0 0 0" />
      <mass
        value="0.32911" />
      <inertia
        ixx="0.00015526"
        ixy="2.7911E-22"
        ixz="-9.9897E-20"
        iyy="0.0020318"
        iyz="3.2157E-21"
        izz="0.0018788" />
    </inertial>
    <visual>
      <origin
        xyz="0 0 0"
        rpy="0 0 0" />
      <geometry>
        <mesh
          filename="package://urdf_Myool/meshes/Back_Left.STL" />
      </geometry>
      <material
        name="">
        <color
          rgba="0.89804 0.91765 0.92941 1" />
      </material>
    </visual>
    <collision>
      <origin
        xyz="0 0 0"
        rpy="0 0 0" />
      <geometry>
        <mesh
          filename="package://urdf_Myool/meshes/Back_Left.STL" />
      </geometry>
    </collision>
  </link>
  <joint
    name="Back_Left_Rocker"
    type="continuous">
    <origin
      xyz="-0.15651 0.20097 0.003175"
      rpy="0 0 0" />
    <parent
      link="base_link" />
    <child
      link="Back_Left" />
    <axis
      xyz="0 1 0" />
  </joint>
  <link
    name="Back_Left_Rear">
    <inertial>
      <origin
        xyz="1.3878E-17 0.021778 -1.3878E-17"
        rpy="0 0 0" />
      <mass
        value="0.84556" />
      <inertia
        ixx="0.001557"
        ixy="7.9263E-20"
        ixz="-3.8952E-11"
        iyy="0.0028888"
        iyz="-2.8717E-09"
        izz="0.001557" />
    </inertial>
    <visual>
      <origin
        xyz="0 0 0"
        rpy="0 0 0" />
      <geometry>
        <mesh
          filename="package://urdf_Myool/meshes/Back_Left_Rear.STL" />
      </geometry>
      <material
        name="">
        <color
          rgba="0.79216 0.81961 0.93333 1" />
      </material>
    </visual>
    <collision>
      <origin
        xyz="0 0 0"
        rpy="0 0 0" />
      <geometry>
        <mesh
          filename="package://urdf_Myool/meshes/Back_Left_Rear.STL" />
      </geometry>
    </collision>
  </link>
  <joint
    name="Back_Left_Rear_Wheel"
    type="continuous">
    <origin
      xyz="-0.1016 0.01465 0"
      rpy="0 0 0" />
    <parent
      link="Back_Left" />
    <child
      link="Back_Left_Rear" />
    <axis
      xyz="0 -1 0" />
  </joint>
  <link
    name="Back_Left_Center">
    <inertial>
      <origin
        xyz="-2.7756E-17 0.021778 -1.1102E-16"
        rpy="0 0 0" />
      <mass
        value="0.84556" />
      <inertia
        ixx="0.001557"
        ixy="-1.4308E-19"
        ixz="-3.8952E-11"
        iyy="0.0028888"
        iyz="-2.8717E-09"
        izz="0.001557" />
    </inertial>
    <visual>
      <origin
        xyz="0 0 0"
        rpy="0 0 0" />
      <geometry>
        <mesh
          filename="package://urdf_Myool/meshes/Back_Left_Center.STL" />
      </geometry>
      <material
        name="">
        <color
          rgba="0.79216 0.81961 0.93333 1" />
      </material>
    </visual>
    <collision>
      <origin
        xyz="0 0 0"
        rpy="0 0 0" />
      <geometry>
        <mesh
          filename="package://urdf_Myool/meshes/Back_Left_Center.STL" />
      </geometry>
    </collision>
  </link>
  <joint
    name="Back_Left_Center_Wheel"
    type="continuous">
    <origin
      xyz="0.1016 0.01465 0"
      rpy="0 0 0" />
    <parent
      link="Back_Left" />
    <child
      link="Back_Left_Center" />
    <axis
      xyz="0 -1 0" />
  </joint>
  <link
    name="Battery">
    <inertial>
      <origin
        xyz="-0.14249 -0.025146 0.037465"
        rpy="0 0 0" />
      <mass
        value="4.2741" />
      <inertia
        ixx="0.016268"
        ixy="4.3801E-18"
        ixz="2.4187E-19"
        iyy="0.030927"
        iyz="-6.5834E-19"
        izz="0.043196" />
    </inertial>
    <visual>
      <origin
        xyz="0 0 0"
        rpy="0 0 0" />
      <geometry>
        <mesh
          filename="package://urdf_Myool/meshes/Battery.STL" />
      </geometry>
      <material
        name="">
        <color
          rgba="0.79216 0.81961 0.93333 1" />
      </material>
    </visual>
    <collision>
      <origin
        xyz="0 0 0"
        rpy="0 0 0" />
      <geometry>
        <mesh
          filename="package://urdf_Myool/meshes/Battery.STL" />
      </geometry>
    </collision>
  </link>
  <joint
    name="Battery_Box"
    type="fixed">
    <origin
      xyz="0.097493 0.025146 0.00635"
      rpy="0 0 0" />
    <parent
      link="base_link" />
    <child
      link="Battery" />
    <axis
      xyz="0 0 0" />
  </joint>
</robot>